Workbook
Name Slicer_Category: #N/A
Name Slicer_Order_month: #N/A
Name Slicer_Region: #N/A

Sheet Sales
A1: ProductID | B1: OrderDate | C1: OrderDate2 | D1: order ID | E1: RegionID | F1: Quantity | G1: Quantity3 | H1: SalesAmount | I1: SalesAmount4 | J1: Weekday
A2: P009 | B2: 2023-01-05 | C2: =TEXT(TEXT(B2,"DD-MM-YYYY"),"mmm") -> Jan | D2: ORD-1000 | E2: R02 | F2: 5 | G2: =ROUND(IF(ISBLANK(F2),AVERAGE($F$2:$F$45),F2),0) -> 5 | H2: 1500 | I2: =ROUND(IF(ISBLANK(H2),AVERAGE($H$2:$H$45),H2),0) -> 1500 | J2: =TEXT(B2,"dddd") -> Thursday
A3: P001 | B3: 44948 | C3: =TEXT(TEXT(B3,"DD-MM-YYYY"),"mmm") -> Jan | D3: ORD-1002 | E3: R01 | F3: 3 | G3: =ROUND(IF(ISBLANK(F3),AVERAGE($F$2:$F$45),F3),0) -> 3 | H3: 450 | I3: =ROUND(IF(ISBLANK(H3),AVERAGE($H$2:$H$45),H3),0) -> 450 | J3: =TEXT(B3,"dddd") -> Sunday
A4: P003 | B4: 2023-02-03 | C4: =TEXT(TEXT(B4,"DD-MM-YYYY"),"mmm") -> Feb | D4: ORD-1003 | E4: R04 | G4: =ROUND(IF(ISBLANK(F4),AVERAGE($F$2:$F$45),F4),0) -> 8 | I4: =ROUND(IF(ISBLANK(H4),AVERAGE($H$2:$H$45),H4),0) -> 2528 | J4: =TEXT(B4,"dddd") -> Friday
A5: P002 | B5: 44959 | C5: =TEXT(TEXT(B5,"DD-MM-YYYY"),"mmm") -> Feb | D5: ORD-1004 | E5: R03 | F5: 8 | G5: =ROUND(IF(ISBLANK(F5),AVERAGE($F$2:$F$45),F5),0) -> 8 | H5: 2400 | I5: =ROUND(IF(ISBLANK(H5),AVERAGE($H$2:$H$45),H5),0) -> 2400 | J5: =TEXT(B5,"dddd") -> Thursday
A6: P005 | B6: 2023-02-28 | C6: =TEXT(TEXT(B6,"DD-MM-YYYY"),"mmm") -> Feb | D6: ORD-1005 | E6: R02 | F6: 15 | G6: =ROUND(IF(ISBLANK(F6),AVERAGE($F$2:$F$45),F6),0) -> 15 | H6: 7500 | I6: =ROUND(IF(ISBLANK(H6),AVERAGE($H$2:$H$45),H6),0) -> 7500 | J6: =TEXT(B6,"dddd") -> Tuesday
A7: P007 | B7: 2023-03-10 | C7: =TEXT(TEXT(B7,"DD-MM-YYYY"),"mmm") -> Mar | D7: ORD-1006 | E7: R01 | F7: 2 | G7: =ROUND(IF(ISBLANK(F7),AVERAGE($F$2:$F$45),F7),0) -> 2 | H7: 300 | I7: =ROUND(IF(ISBLANK(H7),AVERAGE($H$2:$H$45),H7),0) -> 300 | J7: =TEXT(B7,"dddd") -> Friday
A8: P003 | B8: 45019 | C8: =TEXT(TEXT(B8,"DD-MM-YYYY"),"mmm") -> Apr | D8: ORD-1008 | E8: R04 | F8: 9 | G8: =ROUND(IF(ISBLANK(F8),AVERAGE($F$2:$F$45),F8),0) -> 9 | I8: =ROUND(IF(ISBLANK(H8),AVERAGE($H$2:$H$45),H8),0) -> 2528 | J8: =TEXT(B8,"dddd") -> Monday
A9: P006 | B9: 2023-04-01 | C9: =TEXT(TEXT(B9,"DD-MM-YYYY"),"mmm") -> Apr | D9: ORD-1009 | E9: R03 | F9: 6 | G9: =ROUND(IF(ISBLANK(F9),AVERAGE($F$2:$F$45),F9),0) -> 6 | H9: 900 | I9: =ROUND(IF(ISBLANK(H9),AVERAGE($H$2:$H$45),H9),0) -> 900 | J9: =TEXT(B9,"dddd") -> Saturday
A10: P001 | B10: 2023-04-15 | C10: =TEXT(TEXT(B10,"DD-MM-YYYY"),"mmm") -> Apr | D10: ORD-1010 | E10: R02 | F10: 7 | G10: =ROUND(IF(ISBLANK(F10),AVERAGE($F$2:$F$45),F10),0) -> 7 | I10: =ROUND(IF(ISBLANK(H10),AVERAGE($H$2:$H$45),H10),0) -> 2528 | J10: =TEXT(B10,"dddd") -> Saturday
A11: P001 | B11: 2023-04-30 | C11: =TEXT(TEXT(B11,"DD-MM-YYYY"),"mmm") -> Apr | D11: ORD-1011 | E11: R01 | F11: 11 | G11: =ROUND(IF(ISBLANK(F11),AVERAGE($F$2:$F$45),F11),0) -> 11 | H11: 3300 | I11: =ROUND(IF(ISBLANK(H11),AVERAGE($H$2:$H$45),H11),0) -> 3300 | J11: =TEXT(B11,"dddd") -> Sunday
A12: P009 | B12: 2023-05-05 | C12: =TEXT(TEXT(B12,"DD-MM-YYYY"),"mmm") -> May | D12: ORD-1012 | E12: R04 | F12: 4 | G12: =ROUND(IF(ISBLANK(F12),AVERAGE($F$2:$F$45),F12),0) -> 4 | H12: 1200 | I12: =ROUND(IF(ISBLANK(H12),AVERAGE($H$2:$H$45),H12),0) -> 1200 | J12: =TEXT(B12,"dddd") -> Friday
A13: P004 | B13: 45047 | C13: =TEXT(TEXT(B13,"DD-MM-YYYY"),"mmm") -> May | D13: ORD-1013 | E13: R03 | F13: 14 | G13: =ROUND(IF(ISBLANK(F13),AVERAGE($F$2:$F$45),F13),0) -> 14 | H13: 4200 | I13: =ROUND(IF(ISBLANK(H13),AVERAGE($H$2:$H$45),H13),0) -> 4200 | J13: =TEXT(B13,"dddd") -> Monday
A14: P006 | B14: 2023-05-22 | C14: =TEXT(TEXT(B14,"DD-MM-YYYY"),"mmm") -> May | D14: ORD-1014 | E14: R02 | F14: 7 | G14: =ROUND(IF(ISBLANK(F14),AVERAGE($F$2:$F$45),F14),0) -> 7 | H14: 2100 | I14: =ROUND(IF(ISBLANK(H14),AVERAGE($H$2:$H$45),H14),0) -> 2100 | J14: =TEXT(B14,"dddd") -> Monday
A15: P006 | B15: 2023-06-08 | C15: =TEXT(TEXT(B15,"DD-MM-YYYY"),"mmm") -> Jun | D15: ORD-1015 | E15: R01 | F15: 3 | G15: =ROUND(IF(ISBLANK(F15),AVERAGE($F$2:$F$45),F15),0) -> 3 | H15: 450 | I15: =ROUND(IF(ISBLANK(H15),AVERAGE($H$2:$H$45),H15),0) -> 450 | J15: =TEXT(B15,"dddd") -> Thursday
A16: P006 | B16: 2023-06-18 | C16: =TEXT(TEXT(B16,"DD-MM-YYYY"),"mmm") -> Jun | D16: ORD-1016 | E16: R04 | F16: 20 | G16: =ROUND(IF(ISBLANK(F16),AVERAGE($F$2:$F$45),F16),0) -> 20 | H16: 8000 | I16: =ROUND(IF(ISBLANK(H16),AVERAGE($H$2:$H$45),H16),0) -> 8000 | J16: =TEXT(B16,"dddd") -> Sunday
A17: P005 | B17: 2023-06-30 | C17: =TEXT(TEXT(B17,"DD-MM-YYYY"),"mmm") -> Jun | D17: ORD-1017 | E17: R03 | F17: 1 | G17: =ROUND(IF(ISBLANK(F17),AVERAGE($F$2:$F$45),F17),0) -> 1 | H17: 150 | I17: =ROUND(IF(ISBLANK(H17),AVERAGE($H$2:$H$45),H17),0) -> 150 | J17: =TEXT(B17,"dddd") -> Friday
A18: P002 | B18: 2023-07-04 | C18: =TEXT(TEXT(B18,"DD-MM-YYYY"),"mmm") -> Jul | D18: ORD-1018 | E18: R02 | F18: 8 | G18: =ROUND(IF(ISBLANK(F18),AVERAGE($F$2:$F$45),F18),0) -> 8 | H18: 2400 | I18: =ROUND(IF(ISBLANK(H18),AVERAGE($H$2:$H$45),H18),0) -> 2400 | J18: =TEXT(B18,"dddd") -> Tuesday
A19: P001 | B19: 45122 | C19: =TEXT(TEXT(B19,"DD-MM-YYYY"),"mmm") -> Jul | D19: ORD-1019 | E19: R01 | G19: =ROUND(IF(ISBLANK(F19),AVERAGE($F$2:$F$45),F19),0) -> 8 | I19: =ROUND(IF(ISBLANK(H19),AVERAGE($H$2:$H$45),H19),0) -> 2528 | J19: =TEXT(B19,"dddd") -> Saturday
A20: P003 | B20: 2023-07-28 | C20: =TEXT(TEXT(B20,"DD-MM-YYYY"),"mmm") -> Jul | D20: ORD-1020 | E20: R04 | F20: 5 | G20: =ROUND(IF(ISBLANK(F20),AVERAGE($F$2:$F$45),F20),0) -> 5 | H20: 1500 | I20: =ROUND(IF(ISBLANK(H20),AVERAGE($H$2:$H$45),H20),0) -> 1500 | J20: =TEXT(B20,"dddd") -> Friday
A21: P005 | B21: 2023-08-05 | C21: =TEXT(TEXT(B21,"DD-MM-YYYY"),"mmm") -> Aug | D21: ORD-1021 | E21: R03 | F21: 13 | G21: =ROUND(IF(ISBLANK(F21),AVERAGE($F$2:$F$45),F21),0) -> 13 | H21: 3900 | I21: =ROUND(IF(ISBLANK(H21),AVERAGE($H$2:$H$45),H21),0) -> 3900 | J21: =TEXT(B21,"dddd") -> Saturday
A22: P006 | B22: 45267 | C22: =TEXT(TEXT(B22,"DD-MM-YYYY"),"mmm") -> Dec | D22: ORD-1022 | E22: R02 | F22: 6 | G22: =ROUND(IF(ISBLANK(F22),AVERAGE($F$2:$F$45),F22),0) -> 6 | H22: 1800 | I22: =ROUND(IF(ISBLANK(H22),AVERAGE($H$2:$H$45),H22),0) -> 1800 | J22: =TEXT(B22,"dddd") -> Thursday
A23: P006 | B23: 2023-08-25 | C23: =TEXT(TEXT(B23,"DD-MM-YYYY"),"mmm") -> Aug | D23: ORD-1023 | E23: R01 | F23: 2 | G23: =ROUND(IF(ISBLANK(F23),AVERAGE($F$2:$F$45),F23),0) -> 2 | H23: 300 | I23: =ROUND(IF(ISBLANK(H23),AVERAGE($H$2:$H$45),H23),0) -> 300 | J23: =TEXT(B23,"dddd") -> Friday
A24: P001 | B24: 2023-09-03 | C24: =TEXT(TEXT(B24,"DD-MM-YYYY"),"mmm") -> Sep | D24: ORD-1024 | E24: R04 | F24: 9 | G24: =ROUND(IF(ISBLANK(F24),AVERAGE($F$2:$F$45),F24),0) -> 9 | H24: 2700 | I24: =ROUND(IF(ISBLANK(H24),AVERAGE($H$2:$H$45),H24),0) -> 2700 | J24: =TEXT(B24,"dddd") -> Sunday
A25: P007 | B25: 2023-09-18 | C25: =TEXT(TEXT(B25,"DD-MM-YYYY"),"mmm") -> Sep | D25: ORD-1025 | E25: R03 | F25: 17 | G25: =ROUND(IF(ISBLANK(F25),AVERAGE($F$2:$F$45),F25),0) -> 17 | H25: 6800 | I25: =ROUND(IF(ISBLANK(H25),AVERAGE($H$2:$H$45),H25),0) -> 6800 | J25: =TEXT(B25,"dddd") -> Monday
A26: P009 | B26: 2023-09-30 | C26: =TEXT(TEXT(B26,"DD-MM-YYYY"),"mmm") -> Sep | D26: ORD-1026 | E26: R02 | F26: 4 | G26: =ROUND(IF(ISBLANK(F26),AVERAGE($F$2:$F$45),F26),0) -> 4 | H26: 1200 | I26: =ROUND(IF(ISBLANK(H26),AVERAGE($H$2:$H$45),H26),0) -> 1200 | J26: =TEXT(B26,"dddd") -> Saturday
A27: P002 | B27: 2023-10-10 | C27: =TEXT(TEXT(B27,"DD-MM-YYYY"),"mmm") -> Oct | D27: ORD-1027 | E27: R01 | F27: 11 | G27: =ROUND(IF(ISBLANK(F27),AVERAGE($F$2:$F$45),F27),0) -> 11 | H27: 3300 | I27: =ROUND(IF(ISBLANK(H27),AVERAGE($H$2:$H$45),H27),0) -> 3300 | J27: =TEXT(B27,"dddd") -> Tuesday
A28: P001 | B28: 45221 | C28: =TEXT(TEXT(B28,"DD-MM-YYYY"),"mmm") -> Oct | D28: ORD-1028 | E28: R04 | F28: 3 | G28: =ROUND(IF(ISBLANK(F28),AVERAGE($F$2:$F$45),F28),0) -> 3 | H28: 900 | I28: =ROUND(IF(ISBLANK(H28),AVERAGE($H$2:$H$45),H28),0) -> 900 | J28: =TEXT(B28,"dddd") -> Sunday
A29: P005 | B29: 2023-11-20 | C29: =TEXT(TEXT(B29,"DD-MM-YYYY"),"mmm") -> Nov | D29: ORD-1030 | E29: R03 | F29: 6 | G29: =ROUND(IF(ISBLANK(F29),AVERAGE($F$2:$F$45),F29),0) -> 6 | H29: 1800 | I29: =ROUND(IF(ISBLANK(H29),AVERAGE($H$2:$H$45),H29),0) -> 1800 | J29: =TEXT(B29,"dddd") -> Monday
A30: P007 | B30: 2023-11-30 | C30: =TEXT(TEXT(B30,"DD-MM-YYYY"),"mmm") -> Nov | D30: ORD-1031 | E30: R02 | F30: 15 | G30: =ROUND(IF(ISBLANK(F30),AVERAGE($F$2:$F$45),F30),0) -> 15 | H30: 7500 | I30: =ROUND(IF(ISBLANK(H30),AVERAGE($H$2:$H$45),H30),0) -> 7500 | J30: =TEXT(B30,"dddd") -> Thursday
A31: P009 | B31: 45242 | C31: =TEXT(TEXT(B31,"DD-MM-YYYY"),"mmm") -> Nov | D31: ORD-1033 | E31: R01 | G31: =ROUND(IF(ISBLANK(F31),AVERAGE($F$2:$F$45),F31),0) -> 8 | I31: =ROUND(IF(ISBLANK(H31),AVERAGE($H$2:$H$45),H31),0) -> 2528 | J31: =TEXT(B31,"dddd") -> Sunday
A32: P004 | B32: 2023-12-25 | C32: =TEXT(TEXT(B32,"DD-MM-YYYY"),"mmm") -> Dec | D32: ORD-1034 | E32: R04 | F32: 4 | G32: =ROUND(IF(ISBLANK(F32),AVERAGE($F$2:$F$45),F32),0) -> 4 | H32: 600 | I32: =ROUND(IF(ISBLANK(H32),AVERAGE($H$2:$H$45),H32),0) -> 600 | J32: =TEXT(B32,"dddd") -> Monday
A33: P008 | B33: 2023-12-31 | C33: =TEXT(TEXT(B33,"DD-MM-YYYY"),"mmm") -> Dec | D33: ORD-1035 | E33: R03 | F33: 9 | G33: =ROUND(IF(ISBLANK(F33),AVERAGE($F$2:$F$45),F33),0) -> 9 | H33: 4500 | I33: =ROUND(IF(ISBLANK(H33),AVERAGE($H$2:$H$45),H33),0) -> 4500 | J33: =TEXT(B33,"dddd") -> Sunday
A34: P006 | B34: 2023-01-18 | C34: =TEXT(TEXT(B34,"DD-MM-YYYY"),"mmm") -> Jan | D34: ORD-1036 | E34: R02 | F34: 12 | G34: =ROUND(IF(ISBLANK(F34),AVERAGE($F$2:$F$45),F34),0) -> 12 | H34: 3600 | I34: =ROUND(IF(ISBLANK(H34),AVERAGE($H$2:$H$45),H34),0) -> 3600 | J34: =TEXT(B34,"dddd") -> Wednesday
A35: P004 | B35: 2023-02-11 | C35: =TEXT(TEXT(B35,"DD-MM-YYYY"),"mmm") -> Feb | D35: ORD-1037 | E35: R01 | F35: 5 | G35: =ROUND(IF(ISBLANK(F35),AVERAGE($F$2:$F$45),F35),0) -> 5 | H35: 750 | I35: =ROUND(IF(ISBLANK(H35),AVERAGE($H$2:$H$45),H35),0) -> 750 | J35: =TEXT(B35,"dddd") -> Saturday
A36: P008 | B36: 2023-03-22 | C36: =TEXT(TEXT(B36,"DD-MM-YYYY"),"mmm") -> Mar | D36: ORD-1038 | E36: R04 | F36: 8 | G36: =ROUND(IF(ISBLANK(F36),AVERAGE($F$2:$F$45),F36),0) -> 8 | H36: 3200 | I36: =ROUND(IF(ISBLANK(H36),AVERAGE($H$2:$H$45),H36),0) -> 3200 | J36: =TEXT(B36,"dddd") -> Wednesday
A37: P008 | B37: 2023-07-07 | C37: =TEXT(TEXT(B37,"DD-MM-YYYY"),"mmm") -> Jul | D37: ORD-1039 | E37: R03 | F37: 3 | G37: =ROUND(IF(ISBLANK(F37),AVERAGE($F$2:$F$45),F37),0) -> 3 | H37: 450 | I37: =ROUND(IF(ISBLANK(H37),AVERAGE($H$2:$H$45),H37),0) -> 450 | J37: =TEXT(B37,"dddd") -> Friday
A38: P001 | B38: 2023-09-09 | C38: =TEXT(TEXT(B38,"DD-MM-YYYY"),"mmm") -> Sep | D38: ORD-1040 | E38: R02 | F38: 10 | G38: =ROUND(IF(ISBLANK(F38),AVERAGE($F$2:$F$45),F38),0) -> 10 | H38: 4000 | I38: =ROUND(IF(ISBLANK(H38),AVERAGE($H$2:$H$45),H38),0) -> 4000 | J38: =TEXT(B38,"dddd") -> Saturday
A39: P009 | B39: 2023-06-03 | C39: =TEXT(TEXT(B39,"DD-MM-YYYY"),"mmm") -> Jun | D39: ORD-1042 | E39: R01 | F39: 14 | G39: =ROUND(IF(ISBLANK(F39),AVERAGE($F$2:$F$45),F39),0) -> 14 | H39: 5600 | I39: =ROUND(IF(ISBLANK(H39),AVERAGE($H$2:$H$45),H39),0) -> 5600 | J39: =TEXT(B39,"dddd") -> Saturday
A40: P002 | B40: 2023-08-19 | C40: =TEXT(TEXT(B40,"DD-MM-YYYY"),"mmm") -> Aug | D40: ORD-1043 | E40: R04 | F40: 7 | G40: =ROUND(IF(ISBLANK(F40),AVERAGE($F$2:$F$45),F40),0) -> 7 | H40: 1050 | I40: =ROUND(IF(ISBLANK(H40),AVERAGE($H$2:$H$45),H40),0) -> 1050 | J40: =TEXT(B40,"dddd") -> Saturday
...

Sheet Products
A1: ProductID | B1: ProductName | C1: Category
A2: P001 | B2: Wireless Mouse | C2: Electronics
A3: P002 | B3: USB-C Hub | C3: Electronics
A4: P003 | B4: Desk Lamp | C4: Home & Office
A5: P004 | B5: Notebook Set | C5: Stationery
A6: P005 | B6: Bluetooth Speaker | C6: Electronics
A7: P006 | B7: Standing Desk | C7: Furniture
A8: P007 | B8: Webcam HD | C8: Electronics
A9: P008 | B9: Ergonomic Chair | C9: Furniture
A10: P009 | B10: Pen Drive 64GB | C10: Electronics

Sheet Regions
A1: RegionID | B1: RegionName | C1: RegionName
A2: R01 | B2: North | C2: =PROPER(B2) -> North
A3: R02 | B3: south | C3: =PROPER(B3) -> South
A4: R03 | B4: East | C4: =PROPER(B4) -> East
A5: R04 | B5: WEST | C5: =PROPER(B5) -> West

Sheet TOTAL SALES
A1: ProductID | B1: ProductName | C1: Category | D1: order ID | E1: Order month | F1: RegionID | G1: Region | H1: SalesAmount | I1: Weekday
A2: P001 | B2: =VLOOKUP(A2,Products!$A$1:$C$10,2,0) -> Wireless Mouse | C2: =VLOOKUP(A2,Products!$A$1:$C$10,3,0) -> Electronics | D2: =VLOOKUP(A2,Sales!$A$1:$I$45,4,0) -> ORD-1002 | E2: =VLOOKUP($A2,Sales!$A$1:$I$45,3,0) -> Jan | F2: =VLOOKUP($A2,Sales!$A$1:$I$45,5,0) -> R01 | G2: =VLOOKUP($F2,Regions!$A$1:$C$5,3,0) -> North | H2: =VLOOKUP($A2,Sales!$A$1:$I$45,9,0) -> 450 | I2: =VLOOKUP($A2,Table2[#All],10,0) -> Sunday
A3: P002 | B3: =VLOOKUP(A3,Products!$A$1:$C$10,2,0) -> USB-C Hub | C3: =VLOOKUP(A3,Products!$A$1:$C$10,3,0) -> Electronics | D3: =VLOOKUP(A3,Sales!$A$1:$I$45,4,0) -> ORD-1004 | E3: =VLOOKUP($A3,Sales!$A$1:$I$45,3,0) -> Feb | F3: =VLOOKUP($A3,Sales!$A$1:$I$45,5,0) -> R03 | G3: =VLOOKUP($F3,Regions!$A$1:$C$5,3,0) -> East | H3: =VLOOKUP($A3,Sales!$A$1:$I$45,9,0) -> 2400 | I3: =VLOOKUP($A3,Table2[#All],10,0) -> Thursday
A4: P003 | B4: =VLOOKUP(A4,Products!$A$1:$C$10,2,0) -> Desk Lamp | C4: =VLOOKUP(A4,Products!$A$1:$C$10,3,0) -> Home & Office | D4: =VLOOKUP(A4,Sales!$A$1:$I$45,4,0) -> ORD-1003 | E4: =VLOOKUP($A4,Sales!$A$1:$I$45,3,0) -> Feb | F4: =VLOOKUP($A4,Sales!$A$1:$I$45,5,0) -> R04 | G4: =VLOOKUP($F4,Regions!$A$1:$C$5,3,0) -> West | H4: =VLOOKUP($A4,Sales!$A$1:$I$45,9,0) -> 2528 | I4: =VLOOKUP($A4,Table2[#All],10,0) -> Friday
A5: P004 | B5: =VLOOKUP(A5,Products!$A$1:$C$10,2,0) -> Notebook Set | C5: =VLOOKUP(A5,Products!$A$1:$C$10,3,0) -> Stationery | D5: =VLOOKUP(A5,Sales!$A$1:$I$45,4,0) -> ORD-1013 | E5: =VLOOKUP($A5,Sales!$A$1:$I$45,3,0) -> May | F5: =VLOOKUP($A5,Sales!$A$1:$I$45,5,0) -> R03 | G5: =VLOOKUP($F5,Regions!$A$1:$C$5,3,0) -> East | H5: =VLOOKUP($A5,Sales!$A$1:$I$45,9,0) -> 4200 | I5: =VLOOKUP($A5,Table2[#All],10,0) -> Monday
A6: P005 | B6: =VLOOKUP(A6,Products!$A$1:$C$10,2,0) -> Bluetooth Speaker | C6: =VLOOKUP(A6,Products!$A$1:$C$10,3,0) -> Electronics | D6: =VLOOKUP(A6,Sales!$A$1:$I$45,4,0) -> ORD-1005 | E6: =VLOOKUP($A6,Sales!$A$1:$I$45,3,0) -> Feb | F6: =VLOOKUP($A6,Sales!$A$1:$I$45,5,0) -> R02 | G6: =VLOOKUP($F6,Regions!$A$1:$C$5,3,0) -> South | H6: =VLOOKUP($A6,Sales!$A$1:$I$45,9,0) -> 7500 | I6: =VLOOKUP($A6,Table2[#All],10,0) -> Tuesday
A7: P006 | B7: =VLOOKUP(A7,Products!$A$1:$C$10,2,0) -> Standing Desk | C7: =VLOOKUP(A7,Products!$A$1:$C$10,3,0) -> Furniture | D7: =VLOOKUP(A7,Sales!$A$1:$I$45,4,0) -> ORD-1009 | E7: =VLOOKUP($A7,Sales!$A$1:$I$45,3,0) -> Apr | F7: =VLOOKUP($A7,Sales!$A$1:$I$45,5,0) -> R03 | G7: =VLOOKUP($F7,Regions!$A$1:$C$5,3,0) -> East | H7: =VLOOKUP($A7,Sales!$A$1:$I$45,9,0) -> 900 | I7: =VLOOKUP($A7,Table2[#All],10,0) -> Saturday
A8: P007 | B8: =VLOOKUP(A8,Products!$A$1:$C$10,2,0) -> Webcam HD | C8: =VLOOKUP(A8,Products!$A$1:$C$10,3,0) -> Electronics | D8: =VLOOKUP(A8,Sales!$A$1:$I$45,4,0) -> ORD-1006 | E8: =VLOOKUP($A8,Sales!$A$1:$I$45,3,0) -> Mar | F8: =VLOOKUP($A8,Sales!$A$1:$I$45,5,0) -> R01 | G8: =VLOOKUP($F8,Regions!$A$1:$C$5,3,0) -> North | H8: =VLOOKUP($A8,Sales!$A$1:$I$45,9,0) -> 300 | I8: =VLOOKUP($A8,Table2[#All],10,0) -> Friday
A9: P008 | B9: =VLOOKUP(A9,Products!$A$1:$C$10,2,0) -> Ergonomic Chair | C9: =VLOOKUP(A9,Products!$A$1:$C$10,3,0) -> Furniture | D9: =VLOOKUP(A9,Sales!$A$1:$I$45,4,0) -> ORD-1035 | E9: =VLOOKUP($A9,Sales!$A$1:$I$45,3,0) -> Dec | F9: =VLOOKUP($A9,Sales!$A$1:$I$45,5,0) -> R03 | G9: =VLOOKUP($F9,Regions!$A$1:$C$5,3,0) -> East | H9: =VLOOKUP($A9,Sales!$A$1:$I$45,9,0) -> 4500 | I9: =VLOOKUP($A9,Table2[#All],10,0) -> Sunday
A10: P009 | B10: =VLOOKUP(A10,Products!$A$1:$C$10,2,0) -> Pen Drive 64GB | C10: =VLOOKUP(A10,Products!$A$1:$C$10,3,0) -> Electronics | D10: =VLOOKUP(A10,Sales!$A$1:$I$45,4,0) -> ORD-1000 | E10: =VLOOKUP($A10,Sales!$A$1:$I$45,3,0) -> Jan | F10: =VLOOKUP($A10,Sales!$A$1:$I$45,5,0) -> R02 | G10: =VLOOKUP($F10,Regions!$A$1:$C$5,3,0) -> South | H10: =VLOOKUP($A10,Sales!$A$1:$I$45,9,0) -> 1500 | I10: =VLOOKUP($A10,Table2[#All],10,0) -> Thursday

Sheet Pivot Tables
A3: Row Labels | B3: Sum of SalesAmount
A4: Jan | B4: 1950 | M4: Row Labels | N4: Sum of SalesAmount
A5: Feb | B5: 12428 | M5: Sunday | N5: 4950
A6: Mar | B6: 300 | M6: Monday | N6: 4200
A7: Apr | B7: 900 | M7: Tuesday | N7: 7500
A8: May | B8: 4200 | M8: Thursday | N8: 3900
A9: Dec | B9: 4500 | M9: Friday | N9: 2828
A10: Grand Total | B10: 24278 | M10: Saturday | N10: 900
M11: Grand Total | N11: 24278
A13: Monthly Sales | M13: Weekely Sale
A19: Row Labels | B19: Sum of SalesAmount | M19: Sum of SalesAmount | N19: Column Labels
A20: Electronics | B20: 12150 | M20: Row Labels | N20: Electronics | O20: Furniture | P20: Home & Office | Q20: Stationery | R20: Grand Total
A21: Furniture | B21: 5400 | M21: East | N21: 2400 | O21: 5400 | Q21: 4200 | R21: 12000
A22: Home & Office | B22: 2528 | M22: North | N22: 750 | R22: 750
A23: Stationery | B23: 4200 | M23: South | N23: 9000 | R23: 9000
A24: Grand Total | B24: 24278 | M24: West | P24: 2528 | R24: 2528
M25: Grand Total | N25: 12150 | O25: 5400 | P25: 2528 | Q25: 4200 | R25: 24278
A28: Top Product | S28: Region & Category Wise

Sheet Dashboard

Sheet Documentation
A1: Date & Time Functions
A2: . I used specific function for ordering date, month, week. I used Function like "TEXT()","MONTH()","YEAR()". This help me identify the trends like monthley,and Weekly.
A4: Connecting Multiple Tables
A5: . I used LOOKUP for connecting multiple table.This feature connect multiple data basse into a single sheet.
A7: Pivot Table Features
A8: . In the use of pivot table we can handle large data in to needfull table, Also grouping and slicing healped report become user friendly.
